Workbook

Sheet StatewideResultsTable
B2: Five Districts, Three Winners from Each
B3: 4 + 5: East of the Mountains
B4: 3 + 8: Southwest WA + I-90 Corridor
B5: 6 + 10: South Sound and Peninsula
B6: 7 + 9: Seattle and South King County
B7: 1 + 2: North Puget Sound
B8: Note: This is not how I would draw the districts, but these combinations make the most for combining districts as they are currently drawn.
E10: WA Congressional Vote Share by Party in August Primary | L10: WA Congressional Vote Share by Party in August Primary
F11: Democratic | G11: Republican | H11: Left-wing | I11: Independent | M11: Total Votes | N11: Democratic | O11: Republican | P11: DSA-adjacent | Q11: Independent
E12: STATEWIDE | F12: =CongressionalAnalysis!E3 -> 0.39463653 | G12: =CongressionalAnalysis!E4 -> 0.35135054 | H12: =CongressionalAnalysis!E5 -> 0.20298072 | I12: =CongressionalAnalysis!E6 -> 0.051032211 | L12: STATEWIDE | M12: =CongressionalAnalysis!L2 -> 0 | N12: =CongressionalAnalysis!M3 -> -0.5333527 | O12: =CongressionalAnalysis!M4 -> -0.22625328 | P12: =CongressionalAnalysis!M5 -> 0.89212661 | Q12: =CongressionalAnalysis!M6 -> -0.13252063
E13: WA-1 (Redmond to Marysville) | F13: =CongressionalAnalysis!E9 -> 0.55262093 | G13: =CongressionalAnalysis!E10 -> 0.26211131 | H13: =CongressionalAnalysis!E11 -> 0.10901584 | I13: =CongressionalAnalysis!E12 -> 0.074875602 | L13: WA-1 (Redmond to Marysville) | M13: =CongressionalAnalysis!L8 | N13: =CongressionalAnalysis!M9 -> -0.33 | O13: =CongressionalAnalysis!M10 -> -0.1 | P13: =CongressionalAnalysis!M11 -> 0.33 | Q13: =CongressionalAnalysis!M12 -> 0.11
E14: WA-2 (Everett to Bellingham) | F14: =CongressionalAnalysis!E14 -> 0.423407 | G14: =CongressionalAnalysis!E15 -> 0.32797003 | H14: =CongressionalAnalysis!E16 -> 0.24775906 | I14: =CongressionalAnalysis!E17 -> 0 | L14: WA-2 (Everett to Bellingham) | M14: =CongressionalAnalysis!L13 | N14: =CongressionalAnalysis!M14 -> -0.85 | O14: =CongressionalAnalysis!M15 -> -0.49 | P14: =CongressionalAnalysis!M16 -> 1.35 | Q14: =CongressionalAnalysis!M17 -> 0
E15: WA-3 (Southwest WA) | F15: =CongressionalAnalysis!E19 -> 0.38108359 | G15: =CongressionalAnalysis!E20 -> 0.42842357 | H15: =CongressionalAnalysis!E21 -> 0.16700001 | I15: =CongressionalAnalysis!E22 -> 0.022816808 | L15: WA-3 (Southwest WA) | M15: =CongressionalAnalysis!L18 | N15: =CongressionalAnalysis!M19 -> -1.38 | O15: =CongressionalAnalysis!M20 -> 0.49 | P15: =CongressionalAnalysis!M21 -> 0.85 | Q15: =CongressionalAnalysis!M22 -> 0.05
E16: WA-4 (Central WA) | F16: =CongressionalAnalysis!E24 -> 0.29917777 | G16: =CongressionalAnalysis!E25 -> 0.63028438 | H16: =CongressionalAnalysis!E26 -> 0 | I16: =CongressionalAnalysis!E27 -> 0.069717722 | L16: WA-4 (Central WA) | M16: =CongressionalAnalysis!L23 | N16: =CongressionalAnalysis!M24 -> -0.13 | O16: =CongressionalAnalysis!M25 -> 0.09 | P16: =CongressionalAnalysis!M26 -> 0 | Q16: =CongressionalAnalysis!M27 -> 0.05
E17: WA-5 (Eastern WA) | F17: =CongressionalAnalysis!E29 -> 0.27535025 | G17: =CongressionalAnalysis!E30 -> 0.47398009 | H17: =CongressionalAnalysis!E31 -> 0.044307548 | I17: =CongressionalAnalysis!E32 -> 0.20551984 | L17: WA-5 (Eastern WA) | M17: =CongressionalAnalysis!L28 | N17: =CongressionalAnalysis!M29 -> -0.04 | O17: =CongressionalAnalysis!M30 -> -0.59 | P17: =CongressionalAnalysis!M31 -> 0.2 | Q17: =CongressionalAnalysis!M32 -> 0.42
E18: WA-6 (Tacoma to the Peninsula) | F18: =CongressionalAnalysis!E34 -> 0.58773157 | G18: =CongressionalAnalysis!E35 -> 0.35255928 | H18: =CongressionalAnalysis!E36 -> 0 | I18: =CongressionalAnalysis!E37 -> 0.059085156 | L18: WA-6 (Tacoma to the Peninsula) | M18: =CongressionalAnalysis!L33 | N18: =CongressionalAnalysis!M34 -> 0.47 | O18: =CongressionalAnalysis!M35 -> -0.61 | P18: =CongressionalAnalysis!M36 -> 0 | Q18: =CongressionalAnalysis!M37 -> 0.14
E19: WA-7 (Seattle) | F19: =CongressionalAnalysis!E39 -> 0 | G19: =CongressionalAnalysis!E40 -> 0.098190928 | H19: =CongressionalAnalysis!E41 -> 0.87829714 | I19: =CongressionalAnalysis!E42 -> 0.019811665 | L19: WA-7 (Seattle) | M19: =CongressionalAnalysis!L38 | N19: =CongressionalAnalysis!M39 -> 0 | O19: =CongressionalAnalysis!M40 -> -0.18 | P19: =CongressionalAnalysis!M41 -> 0.34 | Q19: =CongressionalAnalysis!M42 -> -0.11
E20: WA-8 (Sammamish to Wenatchee) | F20: =CongressionalAnalysis!E44 -> 0.53685309 | G20: =CongressionalAnalysis!E45 -> 0.43633374 | H20: =CongressionalAnalysis!E46 -> 0 | I20: =CongressionalAnalysis!E47 -> 0.024934102 | L20: WA-8 (Sammamish to Wenatchee) | M20: =CongressionalAnalysis!L43 | N20: =CongressionalAnalysis!M44 -> -0.39 | O20: =CongressionalAnalysis!M45 -> 0.36 | P20: =CongressionalAnalysis!M46 -> 0 | Q20: =CongressionalAnalysis!M47 -> 0.02
E21: WA-9 (Bellevue to Federal Way) | F21: =CongressionalAnalysis!E49 -> 0.47131838 | G21: =CongressionalAnalysis!E50 -> 0.21825564 | H21: =CongressionalAnalysis!E51 -> 0.29780269 | I21: =CongressionalAnalysis!E52 -> 0.011155132 | L21: WA-9 (Bellevue to Federal Way) | M21: =CongressionalAnalysis!L48 | N21: =CongressionalAnalysis!M49 -> -0.77 | O21: =CongressionalAnalysis!M50 -> 0.31 | P21: =CongressionalAnalysis!M51 -> 0.56 | Q21: =CongressionalAnalysis!M52 -> -0.06
E22: WA-10 (Olympia to Puyallup) | F22: =CongressionalAnalysis!E54 -> 0.47260169 | G22: =CongressionalAnalysis!E55 -> 0.31395826 | H22: =CongressionalAnalysis!E56 -> 0.19733585 | I22: =CongressionalAnalysis!E57 -> 0.013750465 | L22: WA-10 (Olympia to Puyallup) | M22: =CongressionalAnalysis!L53 | N22: =CongressionalAnalysis!M54 -> -0.71 | O22: =CongressionalAnalysis!M55 -> -0.67 | P22: =CongressionalAnalysis!M56 -> 1.44 | Q22: =CongressionalAnalysis!M57 -> -0.05
E30: Source: https://www.sos.wa.gov/elections/data-research/election-data-and-maps/reports-data-and-statistics/voter-turnout-election
E31: Mid-Cycle Primary Turnout (WA Secretary of State)
E32: 2010
E33: 2014
E34: 2018
E35: 2022
E36: 2026

Sheet KeyRacesTable
B2: Multiparty Bellweather Legislative Races
C3: Candidate | D3: Party | E3: Vote Share
B4: 43rd District Senate, Seattle | C4: Jamie Pedersen | D4: Democratic | E4: =KeyRaces!D100 -> 0.66673652
C5: Hannah Sabio-Howell | D5: Left-wing | E5: =KeyRaces!D101 -> 0.2354821
B6: 37th District Rep #1, Seattle | C6: Sharon Tomiko Santos | D6: Democratic | E6: =KeyRaces!D97 -> 0.47885903
C7: Kelabe Tewolde | D7: Left-wing | E7: =KeyRaces!D98 -> 0.51467584
B8: 6th District Rep #1, Spokane | C8: Four Republicans | D8: Republican | E8: =SUM(KeyRaces!D82,KeyRaces!D83,KeyRaces!D85,KeyRaces!D87) -> 0.57365642
C9: Two Democrats | D9: Democratic | E9: =SUM(KeyRaces!D86,KeyRaces!D84) -> 0.42373068
B10: 6th District Rep #2, Spokane | C10: Jonathan Bingle | D10: Republican | E10: =KeyRaces!D89 -> 0.50566641
C11: Julia Payne | D11: Democratic | E11: =KeyRaces!D90 -> 0.24967466
C12: Aaron M. Croft | D12: Independent | E12: =KeyRaces!D91 -> 0.24265264
B13: 14th District Rep #2, Yakima | C13: Deb Manjarrez | D13: Republican | E13: =KeyRaces!D93 -> 0.51035954
C14: Tony G. Sandoval | D14: Democratic | E14: =KeyRaces!D94 -> 0.18327239
C15: Ezequiel Morfin | D15: Left-wing | E15: =KeyRaces!D95 -> 0.30408288

Sheet StatewideResultsFinal
A1: Race | B1: Candidate | C1: Party | D1: Total Votes | E1: Vote Share
A2: U.S. Representative - Congressional District 1 | B2: Benjamin Kincaid | C2: (Prefers Democratic Party) | D2: 3580 | E2: 0.022295155
A3: U.S. Representative - Congressional District 1 | B3: Suzan DelBene | C3: (Prefers Democratic Party) | D3: 85156 | E3: 0.53032577
A4: U.S. Representative - Congressional District 1 | B4: Bryce Nickel | C4: (Prefers Democratic Party) | D4: 3929 | E4: 0.024468622
A5: U.S. Representative - Congressional District 1 | B5: James Etzkorn | C5: (Prefers Independent Party) | D5: 12023 | E5: 0.074875602
A6: U.S. Representative - Congressional District 1 | B6: Hunter Gordon | C6: (Prefers Democratic Party) | D6: 10014 | E6: 0.062364158
A7: U.S. Representative - Congressional District 1 | B7: Mary Silva | C7: (Prefers Republican Party) | D7: 42088 | E7: 0.26211131
A8: U.S. Representative - Congressional District 1 | B8: Catherine Hildebrand | C8: (Prefers Democratic Party) | D8: 3562 | E8: 0.022183057
A9: U.S. Representative - Congressional District 1 | B9: Write-In | D9: 221 | E9: 0.0013763211
A10: U.S. Representative - Congressional District 2 | B10: Edwin H. Feller | C10: (Prefers Republican Party) | D10: 68713 | E10: 0.32797003
A11: U.S. Representative - Congressional District 2 | B11: Tomas Scheel | C11: (Prefers Democratic Party) | D11: 29133 | E11: 0.13905303
A12: U.S. Representative - Congressional District 2 | B12: Devin Hermanson | C12: (Prefers Democratic Party) | D12: 22775 | E12: 0.10870603
A13: U.S. Representative - Congressional District 2 | B13: Rick Larsen | C13: (Prefers Democratic Party) | D13: 88708 | E13: 0.423407
A14: U.S. Representative - Congressional District 2 | B14: Write-In | D14: 181 | E14: 0.00086392058
A15: U.S. Representative - Congressional District 3 | B15: Marie Gluesenkamp Perez | C15: (Prefers Democratic Party) | D15: 78025 | E15: 0.36376818
A16: U.S. Representative - Congressional District 3 | B16: Brent Hennrich | C16: (Prefers Democratic Party) | D16: 35820 | E16: 0.16700001
A17: U.S. Representative - Congressional District 3 | B17: John P. Roco | C17: (Prefers Republican Party) | D17: 4102 | E17: 0.019124346
A18: U.S. Representative - Congressional District 3 | B18: John Saulie-Rohman | C18: (Prefers Independent Party) | D18: 3549 | E18: 0.016546149
A19: U.S. Representative - Congressional District 3 | B19: Troy Rasband | C19: (Prefers Democratic Party) | D19: 2058 | E19: 0.0095948082
A20: U.S. Representative - Congressional District 3 | B20: John Braun | C20: (Prefers Republican Party) | D20: 85064 | E20: 0.3965854
A21: U.S. Representative - Congressional District 3 | B21: Antony Barran | C21: (Prefers Cascade Party) | D21: 1345 | E21: 0.0062706594
A22: U.S. Representative - Congressional District 3 | B22: Austin Braswell | C22: (Prefers Democratic Party) | D22: 1656 | E22: 0.0077206037
A23: U.S. Representative - Congressional District 3 | B23: Lawrence Kellogg | C23: (Prefers Republican Party) | D23: 2727 | E23: 0.01271382
A24: U.S. Representative - Congressional District 3 | B24: Write-in | D24: 145 | E24: 0.00067601904
A25: U.S. Representative - Congressional District 4 | B25: Jacek "Jack" Kobiesa | C25: (States No Party Preference) | D25: 2214 | E25: 0.015519308
A26: U.S. Representative - Congressional District 4 | B26: Amanda McKinney | C26: (Prefers Republican Party) | D26: 49652 | E26: 0.34804186
A27: U.S. Representative - Congressional District 4 | B27: John Duresky | C27: (Prefers Democratic Party) | D27: 42681 | E27: 0.29917777
A28: U.S. Representative - Congressional District 4 | B28: John C. Hughs | C28: (Prefers Republican Party) | D28: 1695 | E28: 0.011881313
A29: U.S. Representative - Congressional District 4 | B29: Favian Valencia | C29: (Prefers Independent Party) | D29: 5776 | E29: 0.040487589
A30: U.S. Representative - Congressional District 4 | B30: Jerrod Sessler | C30: (Prefers Republican Party) | D30: 20808 | E30: 0.14585626
A31: U.S. Representative - Congressional District 4 | B31: Devin Poore | C31: (Prefers Cascade Party) | D31: 1956 | E31: 0.013710825
A32: U.S. Representative - Congressional District 4 | B32: Ken Vaz | C32: (Prefers Republican Party) | D32: 477 | E32: 0.0033435908
A33: U.S. Representative - Congressional District 4 | B33: Zac Rossi | C33: (States No Party Preference) | D33: 879 | E33: 0.0061614597
A34: U.S. Representative - Congressional District 4 | B34: Elpidia Saavedra | C34: (Prefers Republican Party) | D34: 1393 | E34: 0.0097644065
A35: U.S. Representative - Congressional District 4 | B35: Matt Boehnke | C35: (Prefers Republican Party) | D35: 15013 | E35: 0.10523549
A36: U.S. Representative - Congressional District 4 | B36: Write-In | D36: 117 | E36: 0.00082012603
A37: U.S. Representative - Congressional District 5 | B37: Nate Powell | C37: (Prefers Independent Party) | D37: 33443 | E37: 0.16376849
A38: U.S. Representative - Congressional District 5 | B38: Carmela Conroy | C38: (Prefers Democratic Party) | D38: 38487 | E38: 0.18846868
A39: U.S. Representative - Congressional District 5 | B39: Matthew Hayes | C39: (Prefers Independent Party) | D39: 2417 | E39: 0.011835913
A40: U.S. Representative - Congressional District 5 | B40: Bajun R. Mavalwalla | C40: (Prefers Democratic Party) | D40: 6482 | E40: 0.03174199
...

Sheet LegislativeAnalysis
A1: Race | B1: Total Votes Cast
A2: U.S. Representative - Congressional District 7 | B2: 220529 | G2: AS OF AUGUST 13th
A3: U.S. Representative - Congressional District 3 | B3: 215930 | G3: Votes Cast (LD Representative) | H3: Average votes per district
A4: U.S. Representative - Congressional District 6 | B4: 212516 | F4: WA 1 | G4: =StatewideResults_Aug13!I2 -> 162698 | H4: =AVERAGE(G4:G13) -> 185384.8
A5: U.S. Representative - Congressional District 2 | B5: 212089 | F5: WA 2 | G5: =StatewideResults_Aug13!I3 -> 212089
A6: U.S. Representative - Congressional District 8 | B6: 193951 | F6: WA 3 | G6: =StatewideResults_Aug13!I4 -> 215930
A7: U.S. Representative - Congressional District 5 | B7: 189719 | F7: WA 4 | G7: =StatewideResults_Aug13!I5 -> 145177
A8: U.S. Representative - Congressional District 1 | B8: 162698 | F8: WA 5 | G8: =StatewideResults_Aug13!I6 -> 189719
A9: U.S. Representative - Congressional District 10 | B9: 157691 | F9: WA 6 | G9: =StatewideResults_Aug13!I7 -> 212516
A10: U.S. Representative - Congressional District 4 | B10: 145177 | F10: WA 7 | G10: =StatewideResults_Aug13!I8 -> 220529
A11: U.S. Representative - Congressional District 9 | B11: 143548 | F11: WA 8 | G11: =StatewideResults_Aug13!I9 -> 193951
A12: State Senator - Legislative District 26 | B12: 51269 | F12: WA 9 | G12: =StatewideResults_Aug13!I10 -> 143548
A13: State Representative Pos. 1 - Legislative District 26 | B13: 51269 | F13: WA 10 | G13: =StatewideResults_Aug13!I11 -> 157691
A14: State Representative Pos. 2 - Legislative District 26 | B14: 51269 | F14: LD 1 | G14: =StatewideResults_Aug13!I36 -> 40105 | H14: =AVERAGE(G14:G62) -> 37833.633
A15: State Senator - Legislative District 35 | B15: 50910 | F15: LD 2 | G15: =StatewideResults_Aug13!I38 -> 32256
A16: State Representative Pos. 1 - Legislative District 35 | B16: 50910 | F16: LD 3 | G16: =StatewideResults_Aug13!I40 -> 42906
A17: State Representative Pos. 2 - Legislative District 35 | B17: 50910 | F17: LD 4 | G17: =StatewideResults_Aug13!I42 -> 42929
A18: State Senator - Legislative District 42 | B18: 50320 | F18: LD 5 | G18: =StatewideResults_Aug13!I44 -> 41818
A19: State Representative Pos. 1 - Legislative District 42 | B19: 50320 | F19: LD 6 | G19: =StatewideResults_Aug13!I46 -> 37834
A20: State Representative Pos. 2 - Legislative District 42 | B20: 50320 | F20: LD 7 | G20: =StatewideResults_Aug13!I48 -> 43719
A21: State Senator - Legislative District 36 | B21: 49797 | F21: LD 8 | G21: =StatewideResults_Aug13!I50 -> 34538
A22: State Representative Pos. 1 - Legislative District 36 | B22: 49797 | F22: LD 9 | G22: =StatewideResults_Aug13!I52 -> 42925
A23: State Representative Pos. 2 - Legislative District 36 | B23: 49797 | F23: LD 10 | G23: =StatewideResults_Aug13!I54 -> 49005
A24: State Representative Pos. 1 - Legislative District 10 | B24: 49005 | F24: LD 11 | G24: =StatewideResults_Aug13!I56 -> 26427
A25: State Representative Pos. 2 - Legislative District 10 | B25: 49005 | F25: LD 12 | G25: =StatewideResults_Aug13!I58 -> 45047
A26: State Representative Pos. 1 - Legislative District 20 | B26: 48776 | F26: LD 13 | G26: =StatewideResults_Aug13!I60 -> 31808
A27: State Representative Pos. 2 - Legislative District 20 | B27: 48776 | F27: LD 14 | G27: =StatewideResults_Aug13!I62 -> 13571
A28: State Representative Pos. 1 - Legislative District 23 | B28: 48430 | F28: LD 15 | G28: =StatewideResults_Aug13!I64 -> 32294
A29: State Representative Pos. 2 - Legislative District 23 | B29: 48430 | F29: LD 16 | G29: =StatewideResults_Aug13!I66 -> 19785
A30: State Representative Pos. 1 - Legislative District 40 | B30: 48106 | F30: LD 17 | G30: =StatewideResults_Aug13!I68 -> 47902
A31: State Representative Pos. 2 - Legislative District 40 | B31: 48106 | F31: LD 18 | G31: =StatewideResults_Aug13!I70 -> 44491
A32: State Representative Pos. 1 - Legislative District 17 | B32: 47902 | F32: LD 19 | G32: =StatewideResults_Aug13!I72 -> 44163
A33: State Representative Pos. 2 - Legislative District 17 | B33: 47902 | F33: LD 20 | G33: =StatewideResults_Aug13!I74 -> 48776
A34: State Representative Pos. 1 - Legislative District 22 | B34: 47074 | F34: LD 21 | G34: =StatewideResults_Aug13!I76 -> 33148
A35: State Representative Pos. 2 - Legislative District 22 | B35: 47074 | F35: LD 22 | G35: =StatewideResults_Aug13!I78 -> 47074
A36: State Senator - Legislative District 46 | B36: 46587 | F36: LD 23 | G36: =StatewideResults_Aug13!I80 -> 48430
A37: State Representative Pos. 1 - Legislative District 46 | B37: 46587 | F37: LD 24 | G37: =StatewideResults_Aug13!I82 -> 39189
A38: State Representative Pos. 2 - Legislative District 46 | B38: 46587 | F38: LD 25 | G38: =StatewideResults_Aug13!I84 -> 29103
A39: State Representative Pos. 1 - Legislative District 12 | B39: 45047 | F39: LD 26 | G39: =StatewideResults_Aug13!I86 -> 51269
A40: State Representative Pos. 2 - Legislative District 12 | B40: 45047 | F40: LD 27 | G40: =StatewideResults_Aug13!I88 -> 34620
...

Sheet CongressionalAnalysis
D1: Latest Vote Total (expected total 1.9M ballots) | E1: Latest Vote Share | F1: Day1_Votes_Aug4 | G1: Day1_VoteShare_Pct | H1: Change from Day 1 Count | I1: Share of Post Day 1 Votes Counted | J1: Change from Day 1 Share | K1: Day2_CumulVotes | L1: Day2_CumulVoteShare_Pct | M1: Day2_ShareChange | N1: Day2_VoteChange | O1: Day2_VoteShare_Pct | P1: Day3_CumulVotes | Q1: Day3_CumulVoteShare_Pct | R1: Day3_ShareChange | S1: Day3_VoteChange | T1: Day3_VoteShare_Pct | U1: Day4_CumulVotes | V1: Day4_CumulVoteShare_Pct | W1: Day4_ShareChange | X1: Day4_VoteChange | Y1: Day4_VoteShare_Pct | Z1: Day5_CumulVotes | AA1: Day5_CumulVoteShare_Pct | AB1: Day5_TotalChange | AC1: Day5_VoteChange | AD1: Day5_VoteShare_Pct | AE1: Day6_CumulVotes | AF1: Day6_CumulVoteShare_Pct | AG1: Day6_TotalChange | AH1: Day6_VoteChange | AI1: Day6_VoteShare_Pct | AJ1: Final_CumulVotes | AK1: Final_CumulVoteShare_Pct | AL1: Final_TotalChange | AM1: Final_VoteChange | AN1: Final_VoteShare_Pct
B2: Total | C2: Total Ballots | D2: =AJ2 -> 1861055 | F2: =SUM(F8,F13,F18,F23,F28,F33,F38,F43,F48,F53) -> 1029284 | H2: =D2-F2 -> 831771 | K2: =SUM(K8,K13,K18,K23,K28,K33,K38,K43,K48,K53) -> 1259898 | N2: =SUM(N8,N13,N18,N23,N28,N33,N38,N43,N48,N53) -> 230614 | P2: =SUM(P8,P13,P18,P23,P28,P33,P38,P43,P48,P53) -> 1514585 | S2: =SUM(S8,S13,S18,S23,S28,S33,S38,S43,S48,S53) -> 254687 | T2: =SUM(T8,T13,T18,T23,T28,T33,T38,T43,T48,T53) -> 0 | U2: =SUM(U8,U13,U18,U23,U28,U33,U38,U43,U48,U53) -> 1688871 | V2: =SUM(V8,V13,V18,V23,V28,V33,V38,V43,V48,V53) -> 0 | W2: =SUM(W8,W13,W18,W23,W28,W33,W38,W43,W48,W53) -> 0 | X2: =SUM(X8,X13,X18,X23,X28,X33,X38,X43,X48,X53) -> 174286 | Y2: =SUM(Y8,Y13,Y18,Y23,Y28,Y33,Y38,Y43,Y48,Y53) -> 0 | Z2: =SUM(Z8,Z13,Z18,Z23,Z28,Z33,Z38,Z43,Z48,Z53) -> 1804194 | ... AN2: =SUM(AN8,AN13,AN18,AN23,AN28,AN33,AN38,AN43,AN48,AN53) -> 0
C3: Democratic | D3: =AJ3 -> 734535 | E3: =AK3 -> 0.39463653 | F3: =SUM(F9,F14,F19,F24,F29,F34,F39,F44,F49,F54) -> 432043 | G3: =F3/(SUM(F$3:F$6)) -> 0.41965438 | H3: =D3-F3 -> 302492 | I3: =H3/SUM(H3:H6) -> 0.3636709 | J3: =I3-G3 -> -0.055983482 | K3: =SUM(K9,K14,K19,K24,K29,K34,K39,K44,K49,K54) -> 520445 | L3: =K3/(SUM(K$3:K$6)) -> 0.41432086 | M3: =(L3-$G3)*100 -> -0.5333527 | N3: =SUM(N9,N14,N19,N24,N29,N34,N39,N44,N49,N54) -> 88402 | O3: =N3/(SUM(N$3:N$6)) -> 0.39009086 | P3: =SUM(P9,P14,P19,P24,P29,P34,P39,P44,P49,P54) -> 615693 | Q3: =P3/(SUM(P$3:P$6)) -> 0.40741804 | R3: =(Q3-$G3)*100 -> -1.2236339 | S3: =SUM(S9,S14,S19,S24,S29,S34,S39,S44,S49,S54) -> 95248 | T3: =S3/(SUM(S$3:S$6)) -> 0.37342345 | U3: =SUM(U9,U14,U19,U24,U29,U34,U39,U44,U49,U54) -> 675820 | V3: =U3/(SUM(U$3:U$6)) -> 0.40099254 | W3: =(V3-$G3)*100 -> -1.866184 | X3: =SUM(X9,X14,X19,X24,X29,X34,X39,X44,X49,X54) -> 60127 | Y3: =X3/(SUM(X$3:X$6)) -> 0.34523803 | Z3: =SUM(Z9,Z14,Z19,Z24,Z29,Z34,Z39,Z44,Z49,Z54) -> 713769 | AA3: =Z3/(SUM(Z$3:Z$6)) -> 0.39646455 | AB3: =(AA3-$G3)*100 -> -2.3189836 | AC3: =SUM(AC9,AC14,AC19,AC24,AC29,AC34,AC39,AC44,AC49,AC54) -> 37949 | AD3: =AC3/(SUM(AC$3:AC$6)) -> 0.33008602 | AE3: =SUM(AE9,AE14,AE19,AE24,AE29,AE34,AE39,AE44,AE49,AE54) -> 723520 | AF3: =AE3/(SUM(AE$3:AE$6)) -> 0.3957569 | AG3: =(AF3-$G3)*100 -> -2.389748 | AH3: =SUM(AH9,AH14,AH19,AH24,AH29,AH34,AH39,AH44,AH49,AH54) -> 9751 | AI3: =AH3/(SUM(AH$3:AH$6)) -> 0.35002513 | AJ3: =SUM(AJ9,AJ14,AJ19,AJ24,AJ29,AJ34,AJ39,AJ44,AJ49,AJ54) -> 734535 | AK3: =AJ3/(SUM(AJ$3:AJ$6)) -> 0.39463653 | AL3: =(AK3-$G3)*100 -> -2.5017853 | AM3: =SUM(AM9,AM14,AM19,AM24,AM29,AM34,AM39,AM44,AM49,AM54) -> 11015 | AN3: =AM3/(SUM(AM$3:AM$6)) -> 0.33275935
C4: Republican | D4: =AJ4 -> 653967 | E4: =AK4 -> 0.35135054 | F4: =SUM(F10,F15,F20,F25,F30,F35,F40,F45,F50,F55) -> 370306 | G4: =F4/(SUM(F$3:F$6)) -> 0.35968766 | H4: =D4-F4 -> 283661 | I4: =H4/SUM(H3:H6) -> 0.34103134 | J4: =I4-G4 -> -0.018656323 | K4: =SUM(K10,K15,K20,K25,K30,K35,K40,K45,K50,K55) -> 448976 | L4: =K4/(SUM(K$3:K$6)) -> 0.35742513 | M4: =(L4-G4)*100 -> -0.22625328 | N4: =SUM(N10,N15,N20,N25,N30,N35,N40,N45,N50,N55) -> 78670 | O4: =N4/(SUM(N$3:N$6)) -> 0.34714653 | P4: =SUM(P10,P15,P20,P25,P30,P35,P40,P45,P50,P55) -> 530129 | Q4: =P4/(SUM(P$3:P$6)) -> 0.3507984 | R4: =(Q4-$G4)*100 -> -0.8889259 | S4: =SUM(S10,S15,S20,S25,S30,S35,S40,S45,S50,S55) -> 81153 | T4: =S4/(SUM(S$3:S$6)) -> 0.31816346 | U4: =SUM(U10,U15,U20,U25,U30,U35,U40,U45,U50,U55) -> 585282 | V4: =U4/(SUM(U$3:U$6)) -> 0.34727252 | W4: =(V4-$G4)*100 -> -1.2415136 | X4: =SUM(X10,X15,X20,X25,X30,X35,X40,X45,X50,X55) -> 55153 | Y4: =X4/(SUM(X$3:X$6)) -> 0.31667825 | Z4: =SUM(Z10,Z15,Z20,Z25,Z30,Z35,Z40,Z45,Z50,Z55) -> 626285 | AA4: =Z4/(SUM(Z$3:Z$6)) -> 0.34787137 | AB4: =(AA4-$G4)*100 -> -1.1816292 | AC4: =SUM(AC10,AC15,AC20,AC25,AC30,AC35,AC40,AC45,AC50,AC55) -> 41003 | AD4: =AC4/(SUM(AC$3:AC$6)) -> 0.35665017 | AE4: =SUM(AE10,AE15,AE20,AE25,AE30,AE35,AE40,AE45,AE50,AE55) -> 639934 | AF4: =AE4/(SUM(AE$3:AE$6)) -> 0.35003635 | AG4: =(AF4-$G4)*100 -> -0.96513132 | AH4: =SUM(AH10,AH15,AH20,AH25,AH30,AH35,AH40,AH45,AH50,AH55) -> 13649 | AI4: =AH4/(SUM(AH$3:AH$6)) -> 0.48994903 | AJ4: =SUM(AJ10,AJ15,AJ20,AJ25,AJ30,AJ35,AJ40,AJ45,AJ50,AJ55) -> 653967 | AK4: =AJ4/(SUM(AJ$3:AJ$6)) -> 0.35135054 | AL4: =(AK4-$G4)*100 -> -0.83371224 | AM4: =SUM(AM10,AM15,AM20,AM25,AM30,AM35,AM40,AM45,AM50,AM55) -> 14033 | AN4: =AM4/(SUM(AM$3:AM$6)) -> 0.42393209
C5: DSA | D5: =AJ5 -> 377807 | E5: =AK5 -> 0.20298072 | F5: =SUM(F11,F16,F21,F26,F31,F36,F41,F46,F51,F56) -> 178464 | G5: =F5/(SUM(F$3:F$6)) -> 0.17334663 | H5: =D5-F5 -> 199343 | I5: =H5/SUM(H3:H6) -> 0.23966005 | J5: =I5-G5 -> 0.066313418 | K5: =SUM(K11,K16,K21,K26,K31,K36,K41,K46,K51,K56) -> 228954 | L5: =K5/(SUM(K$3:K$6)) -> 0.1822679 | M5: =(L5-G5)*100 -> 0.89212661 | N5: =SUM(N11,N16,N21,N26,N31,N36,N41,N46,N51,N56) -> 50490 | O5: =N5/(SUM(N$3:N$6)) -> 0.22279685 | P5: =SUM(P11,P16,P21,P26,P31,P36,P41,P46,P51,P56) -> 294948 | Q5: =P5/(SUM(P$3:P$6)) -> 0.19517379 | R5: =(Q5-$G5)*100 -> 2.1827158 | S5: =SUM(S11,S16,S21,S26,S31,S36,S41,S46,S51,S56) -> 65994 | T5: =S5/(SUM(S$3:S$6)) -> 0.25873202 | U5: =SUM(U11,U16,U21,U26,U31,U36,U41,U46,U51,U56) -> 346289 | V5: =U5/(SUM(U$3:U$6)) -> 0.20546789 | W5: =(V5-$G5)*100 -> 3.2121252 | X5: =SUM(X11,X16,X21,X26,X31,X36,X41,X46,X51,X56) -> 51341 | Y5: =X5/(SUM(X$3:X$6)) -> 0.29479045 | Z5: =SUM(Z11,Z16,Z21,Z26,Z31,Z36,Z41,Z46,Z51,Z56) -> 371043 | AA5: =Z5/(SUM(Z$3:Z$6)) -> 0.20609664 | AB5: =(AA5-$G5)*100 -> 3.2750009 | AC5: =SUM(AC11,AC16,AC21,AC26,AC31,AC36,AC41,AC46,AC51,AC56) -> 24754 | AD5: =AC5/(SUM(AC$3:AC$6)) -> 0.21531396 | AE5: =SUM(AE11,AE16,AE21,AE26,AE31,AE36,AE41,AE46,AE51,AE56) -> 372949 | AF5: =AE5/(SUM(AE$3:AE$6)) -> 0.2039987 | AG5: =(AF5-$G5)*100 -> 3.0652069 | AH5: =SUM(AH11,AH16,AH21,AH26,AH31,AH36,AH41,AH46,AH51,AH56) -> 1906 | AI5: =AH5/(SUM(AH$3:AH$6)) -> 0.068418408 | AJ5: =SUM(AJ11,AJ16,AJ21,AJ26,AJ31,AJ36,AJ41,AJ46,AJ51,AJ56) -> 377807 | AK5: =AJ5/(SUM(AJ$3:AJ$6)) -> 0.20298072 | AL5: =(AK5-$G5)*100 -> 2.9634086 | AM5: =SUM(AM11,AM16,AM21,AM26,AM31,AM36,AM41,AM46,AM51,AM56) -> 4858 | AN5: =AM5/(SUM(AM$3:AM$6)) -> 0.1467585
C6: Independent | D6: =AJ6 -> 94986 | E6: =AK6 -> 0.051032211 | F6: =SUM(F12,F17,F22,F27,F32,F37,F42,F47,F52,F57) -> 48708 | G6: =F6/(SUM(F$3:F$6)) -> 0.047311322 | H6: =D6-F6 -> 46278 | I6: =H6/SUM(H3:H6) -> 0.055637709 | J6: =I6-G6 -> 0.0083263868 | K6: =SUM(K12,K17,K22,K27,K32,K37,K42,K47,K52,K57) -> 57765 | L6: =K6/(SUM(K$3:K$6)) -> 0.045986116 | M6: =(L6-G6)*100 -> -0.13252063 | N6: =SUM(N12,N17,N22,N27,N32,N37,N42,N47,N52,N57) -> 9057 | O6: =N6/(SUM(N$3:N$6)) -> 0.039965758 | P6: =SUM(P12,P17,P22,P27,P32,P37,P42,P47,P52,P57) -> 70437 | Q6: =P6/(SUM(P$3:P$6)) -> 0.046609763 | R6: =(Q6-$G6)*100 -> -0.070155953 | S6: =SUM(S12,S17,S22,S27,S32,S37,S42,S47,S52,S57) -> 12672 | T6: =S6/(SUM(S$3:S$6)) -> 0.049681064 | U6: =SUM(U12,U17,U22,U27,U32,U37,U42,U47,U52,U57) -> 77977 | V6: =U6/(SUM(U$3:U$6)) -> 0.046267047 | W6: =(V6-$G6)*100 -> -0.10442757 | X6: =SUM(X12,X17,X22,X27,X32,X37,X42,X47,X52,X57) -> 7540 | Y6: =X6/(SUM(X$3:X$6)) -> 0.043293275 | Z6: =SUM(Z12,Z17,Z22,Z27,Z32,Z37,Z42,Z47,Z52,Z57) -> 89238 | AA6: =Z6/(SUM(Z$3:Z$6)) -> 0.049567442 | AB6: =(AA6-$G6)*100 -> 0.22561192 | AC6: =SUM(AC12,AC17,AC22,AC27,AC32,AC37,AC42,AC47,AC52,AC57) -> 11261 | AD6: =AC6/(SUM(AC$3:AC$6)) -> 0.097949846 | AE6: =SUM(AE12,AE17,AE22,AE27,AE32,AE37,AE42,AE47,AE52,AE57) -> 91790 | AF6: =AE6/(SUM(AE$3:AE$6)) -> 0.050208047 | AG6: =(AF6-$G6)*100 -> 0.28967245 | AH6: =SUM(AH12,AH17,AH22,AH27,AH32,AH37,AH42,AH47,AH52,AH57) -> 2552 | AI6: =AH6/(SUM(AH$3:AH$6)) -> 0.091607438 | AJ6: =SUM(AJ12,AJ17,AJ22,AJ27,AJ32,AJ37,AJ42,AJ47,AJ52,AJ57) -> 94986 | AK6: =AJ6/(SUM(AJ$3:AJ$6)) -> 0.051032211 | AL6: =(AK6-$G6)*100 -> 0.3720889 | AM6: =SUM(AM12,AM17,AM22,AM27,AM32,AM37,AM42,AM47,AM52,AM57) -> 3196 | AN6: =AM6/(SUM(AM$3:AM$6)) -> 0.096550057
C7: Average Ballots per district | D7: =D2/10 -> 186105.5 | J7: =I7-G7 -> 0
B8: District 1 - Redmond to Marysville | C8: Total Ballots | D8: =AJ8 -> 163014 | F8: =KeyRaces!E2 -> 98597 | G8: =KeyRaces!F2 | H8: =D8-F8 -> 64417 | K8: =KeyRaces!K2 -> 113370 | L8: =KeyRaces!L2 | N8: =KeyRaces!N2 -> 14773 | O8: =KeyRaces!O2 | P8: =KeyRaces!P2 -> 150766 | Q8: =KeyRaces!Q2 | S8: =KeyRaces!S2 -> 37396 | T8: =KeyRaces!T2 | U8: =KeyRaces!U2 -> 159269 | V8: =KeyRaces!V2 | W8: =KeyRaces!W2 | X8: =KeyRaces!X2 -> 8503 | Y8: =KeyRaces!Y2 | Z8: =KeyRaces!Z2 -> 161993 | ... AN8: =KeyRaces!AN2 -> 0
C9: Democratic | D9: =AJ9 -> 88736 | E9: =AK9 -> 0.55262093 | F9: =SUMIF(KeyRaces!$B$3:$B$9,CongressionalAnalysis!$C9,KeyRaces!E$3:E$9) -> 54882 | G9: =SUMIF(KeyRaces!$B$3:$B$9,CongressionalAnalysis!$C9,KeyRaces!F$3:F$9) -> 0.5653 | H9: =D9-F9 -> 33854 | I9: =H9/SUM(H9:H12) -> 0.53404215 | J9: =I9-G9 -> -0.03125785 | K9: =SUMIF(KeyRaces!$B$3:$B$9,CongressionalAnalysis!$C9,KeyRaces!K$3:K$9) -> 62695 | L9: =SUMIF(KeyRaces!$B$3:$B$9,CongressionalAnalysis!$C9,KeyRaces!L$3:L$9) -> 0.562 | M9: =(L9-G9)*100 -> -0.33 | N9: =SUMIF(KeyRaces!$B$3:$B$9,CongressionalAnalysis!$C9,KeyRaces!N$3:N$9) -> 7813 | O9: =SUMIF(KeyRaces!$B$3:$B$9,CongressionalAnalysis!$C9,KeyRaces!O$3:O$9) -> 0.5402 | P9: =SUMIF(KeyRaces!$B$3:$B$9,CongressionalAnalysis!$C9,KeyRaces!P$3:P$9) -> 81786 | Q9: =SUMIF(KeyRaces!$B$3:$B$9,CongressionalAnalysis!$C9,KeyRaces!Q$3:Q$9) -> 0.55204115 | R9: =(Q9-$G9)*100 -> -1.3258853 | S9: =SUMIF(KeyRaces!$B$3:$B$9,CongressionalAnalysis!$C9,KeyRaces!S$3:S$9) -> 19091 | T9: =SUMIF(KeyRaces!$B$3:$B$9,CongressionalAnalysis!$C9,KeyRaces!T$3:T$9) -> 0.52155502 | U9: =SUMIF(KeyRaces!$B$3:$B$9,CongressionalAnalysis!$C9,KeyRaces!U$3:U$9) -> 86654 | V9: =SUMIF(KeyRaces!$B$3:$B$9,CongressionalAnalysis!$C9,KeyRaces!V$3:V$9) -> 0.55292594 | W9: =SUMIF(KeyRaces!$B$3:$B$9,CongressionalAnalysis!$C9,KeyRaces!W$3:W$9) -> -1.24 | X9: =SUMIF(KeyRaces!$B$3:$B$9,CongressionalAnalysis!$C9,KeyRaces!X$3:X$9) -> 4868 | Y9: =SUMIF(KeyRaces!$B$3:$B$9,CongressionalAnalysis!$C9,KeyRaces!Y$3:Y$9) -> 0.56822692 | Z9: =SUMIF(KeyRaces!$B$3:$B$9,CongressionalAnalysis!$C9,KeyRaces!Z$3:Z$9) -> 88174 | ... AN9: =SUMIF(KeyRaces!$B$3:$B$9,CongressionalAnalysis!$C9,KeyRaces!AN$3:AN$9) -> 0.50138889
C10: Republican | D10: =AJ10 -> 42088 | E10: =AK10 -> 0.26211131 | F10: =SUMIF(KeyRaces!$B$3:$B$9,CongressionalAnalysis!$C10,KeyRaces!E$3:E$9) -> 26389 | G10: =SUMIF(KeyRaces!$B$3:$B$9,CongressionalAnalysis!$C10,KeyRaces!F$3:F$9) -> 0.2718 | H10: =D10-F10 -> 15699 | I10: =H10/SUM(H9:H12) -> 0.24764955 | J10: =I10-G10 -> -0.024150454 | K10: =SUMIF(KeyRaces!$B$3:$B$9,CongressionalAnalysis!$C10,KeyRaces!K$3:K$9) -> 30202 | L10: =SUMIF(KeyRaces!$B$3:$B$9,CongressionalAnalysis!$C10,KeyRaces!L$3:L$9) -> 0.2708 | M10: =(L10-G10)*100 -> -0.1 | N10: =SUMIF(KeyRaces!$B$3:$B$9,CongressionalAnalysis!$C10,KeyRaces!N$3:N$9) -> 3813 | O10: =SUMIF(KeyRaces!$B$3:$B$9,CongressionalAnalysis!$C10,KeyRaces!O$3:O$9) -> 0.2637 | P10: =SUMIF(KeyRaces!$B$3:$B$9,CongressionalAnalysis!$C10,KeyRaces!P$3:P$9) -> 39700 | Q10: =SUMIF(KeyRaces!$B$3:$B$9,CongressionalAnalysis!$C10,KeyRaces!Q$3:Q$9) -> 0.26796803 | R10: =(Q10-$G10)*100 -> -0.38319672 | S10: =SUMIF(KeyRaces!$B$3:$B$9,CongressionalAnalysis!$C10,KeyRaces!S$3:S$9) -> 9498 | T10: =SUMIF(KeyRaces!$B$3:$B$9,CongressionalAnalysis!$C10,KeyRaces!T$3:T$9) -> 0.25947984 | U10: =SUMIF(KeyRaces!$B$3:$B$9,CongressionalAnalysis!$C10,KeyRaces!U$3:U$9) -> 41269 | V10: =SUMIF(KeyRaces!$B$3:$B$9,CongressionalAnalysis!$C10,KeyRaces!V$3:V$9) -> 0.26333119 | W10: =SUMIF(KeyRaces!$B$3:$B$9,CongressionalAnalysis!$C10,KeyRaces!W$3:W$9) -> -0.85 | X10: =SUMIF(KeyRaces!$B$3:$B$9,CongressionalAnalysis!$C10,KeyRaces!X$3:X$9) -> 1569 | Y10: =SUMIF(KeyRaces!$B$3:$B$9,CongressionalAnalysis!$C10,KeyRaces!Y$3:Y$9) -> 0.18314462 | Z10: =SUMIF(KeyRaces!$B$3:$B$9,CongressionalAnalysis!$C10,KeyRaces!Z$3:Z$9) -> 41865 | ... AN10: =SUMIF(KeyRaces!$B$3:$B$9,CongressionalAnalysis!$C10,KeyRaces!AN$3:AN$9) -> 0.2
C11: DSA | D11: =AJ11 -> 17505 | E11: =AK11 -> 0.10901584 | F11: =SUMIF(KeyRaces!$B$3:$B$9,CongressionalAnalysis!$C11,KeyRaces!E$3:E$9) -> 8922 | G11: =SUMIF(KeyRaces!$B$3:$B$9,CongressionalAnalysis!$C11,KeyRaces!F$3:F$9) -> 0.0919 | H11: =D11-F11 -> 8583 | I11: =H11/SUM(H9:H12) -> 0.13539563 | J11: =I11-G11 -> 0.043495634 | K11: =SUMIF(KeyRaces!$B$3:$B$9,CongressionalAnalysis!$C11,KeyRaces!K$3:K$9) -> 10619 | L11: =SUMIF(KeyRaces!$B$3:$B$9,CongressionalAnalysis!$C11,KeyRaces!L$3:L$9) -> 0.0952 | M11: =(L11-G11)*100 -> 0.33 | N11: =SUMIF(KeyRaces!$B$3:$B$9,CongressionalAnalysis!$C11,KeyRaces!N$3:N$9) -> 1697 | O11: =SUMIF(KeyRaces!$B$3:$B$9,CongressionalAnalysis!$C11,KeyRaces!O$3:O$9) -> 0.1173 | P11: =SUMIF(KeyRaces!$B$3:$B$9,CongressionalAnalysis!$C11,KeyRaces!P$3:P$9) -> 15540 | Q11: =SUMIF(KeyRaces!$B$3:$B$9,CongressionalAnalysis!$C11,KeyRaces!Q$3:Q$9) -> 0.10489227 | R11: =(Q11-$G11)*100 -> 1.2992273 | S11: =SUMIF(KeyRaces!$B$3:$B$9,CongressionalAnalysis!$C11,KeyRaces!S$3:S$9) -> 4921 | T11: =SUMIF(KeyRaces!$B$3:$B$9,CongressionalAnalysis!$C11,KeyRaces!T$3:T$9) -> 0.13443886 | U11: =SUMIF(KeyRaces!$B$3:$B$9,CongressionalAnalysis!$C11,KeyRaces!U$3:U$9) -> 16896 | V11: =SUMIF(KeyRaces!$B$3:$B$9,CongressionalAnalysis!$C11,KeyRaces!V$3:V$9) -> 0.1078108 | W11: =SUMIF(KeyRaces!$B$3:$B$9,CongressionalAnalysis!$C11,KeyRaces!W$3:W$9) -> 1.58 | X11: =SUMIF(KeyRaces!$B$3:$B$9,CongressionalAnalysis!$C11,KeyRaces!X$3:X$9) -> 1356 | Y11: =SUMIF(KeyRaces!$B$3:$B$9,CongressionalAnalysis!$C11,KeyRaces!Y$3:Y$9) -> 0.15828178 | Z11: =SUMIF(KeyRaces!$B$3:$B$9,CongressionalAnalysis!$C11,KeyRaces!Z$3:Z$9) -> 17273 | ... AN11: =SUMIF(KeyRaces!$B$3:$B$9,CongressionalAnalysis!$C11,KeyRaces!AN$3:AN$9) -> 0.22083333
C12: Independent | D12: =AJ12 -> 12023 | E12: =AK12 -> 0.074875602 | F12: =SUMIF(KeyRaces!$B$3:$B$9,CongressionalAnalysis!$C12,KeyRaces!E$3:E$9) -> 6767 | G12: =SUMIF(KeyRaces!$B$3:$B$9,CongressionalAnalysis!$C12,KeyRaces!F$3:F$9) -> 0.0697 | H12: =D12-F12 -> 5256 | I12: =H12/SUM(H9:H12) -> 0.08291267 | J12: =I12-G12 -> 0.01321267 | K12: =SUMIF(KeyRaces!$B$3:$B$9,CongressionalAnalysis!$C12,KeyRaces!K$3:K$9) -> 7898 | L12: =SUMIF(KeyRaces!$B$3:$B$9,CongressionalAnalysis!$C12,KeyRaces!L$3:L$9) -> 0.0708 | M12: =(L12-G12)*100 -> 0.11 | N12: =SUMIF(KeyRaces!$B$3:$B$9,CongressionalAnalysis!$C12,KeyRaces!N$3:N$9) -> 1131 | O12: =SUMIF(KeyRaces!$B$3:$B$9,CongressionalAnalysis!$C12,KeyRaces!O$3:O$9) -> 0.0782 | P12: =SUMIF(KeyRaces!$B$3:$B$9,CongressionalAnalysis!$C12,KeyRaces!P$3:P$9) -> 10917 | Q12: =SUMIF(KeyRaces!$B$3:$B$9,CongressionalAnalysis!$C12,KeyRaces!Q$3:Q$9) -> 0.073687834 | R12: =(Q12-$G12)*100 -> 0.39878341 | S12: =SUMIF(KeyRaces!$B$3:$B$9,CongressionalAnalysis!$C12,KeyRaces!S$3:S$9) -> 3019 | T12: =SUMIF(KeyRaces!$B$3:$B$9,CongressionalAnalysis!$C12,KeyRaces!T$3:T$9) -> 0.082477325 | U12: =SUMIF(KeyRaces!$B$3:$B$9,CongressionalAnalysis!$C12,KeyRaces!U$3:U$9) -> 11689 | V12: =SUMIF(KeyRaces!$B$3:$B$9,CongressionalAnalysis!$C12,KeyRaces!V$3:V$9) -> 0.074585723 | W12: =SUMIF(KeyRaces!$B$3:$B$9,CongressionalAnalysis!$C12,KeyRaces!W$3:W$9) -> 0.49 | X12: =SUMIF(KeyRaces!$B$3:$B$9,CongressionalAnalysis!$C12,KeyRaces!X$3:X$9) -> 772 | Y12: =SUMIF(KeyRaces!$B$3:$B$9,CongressionalAnalysis!$C12,KeyRaces!Y$3:Y$9) -> 0.090113225 | Z12: =SUMIF(KeyRaces!$B$3:$B$9,CongressionalAnalysis!$C12,KeyRaces!Z$3:Z$9) -> 11920 | ... AN12: =SUMIF(KeyRaces!$B$3:$B$9,CongressionalAnalysis!$C12,KeyRaces!AN$3:AN$9) -> 0.077777778
B13: District 2 - Everett to Bellingham | C13: Total Ballots | D13: =AJ13 -> 212654 | F13: =KeyRaces!E10 -> 125339 | G13: =KeyRaces!F10 | H13: =D13-F13 -> 87315 | K13: =KeyRaces!K10 -> 155944 | L13: =KeyRaces!L10 | N13: =KeyRaces!N10 -> 30605 | O13: =KeyRaces!O10 | P13: =KeyRaces!P10 -> 190784 | Q13: =KeyRaces!Q10 | S13: =KeyRaces!S10 -> 34840 | T13: =KeyRaces!T10 | U13: =KeyRaces!U10 -> 199931 | V13: =KeyRaces!V10 | W13: =KeyRaces!W10 | X13: =KeyRaces!X10 -> 9147 | Y13: =KeyRaces!Y10 | Z13: =KeyRaces!Z10 -> 209866 | ... AN13: =KeyRaces!AN10 -> 0
C14: Democratic | D14: =AJ14 -> 88708 | E14: =AK14 -> 0.423407 | F14: =SUMIF(KeyRaces!$B$11:$B$14,CongressionalAnalysis!$C9,KeyRaces!E$11:E$14) -> 55387 | G14: =SUMIF(KeyRaces!$B$11:$B$14,CongressionalAnalysis!$C9,KeyRaces!F$11:F$14) -> 0.4485 | H14: =D14-F14 -> 33321 | I14: =H14/SUM(H14:H17) -> 0.38771497 | J14: =I14-G14 -> -0.060785029 | K14: =SUMIF(KeyRaces!$B$11:$B$14,CongressionalAnalysis!$C9,KeyRaces!K$11:K$14) -> 67544 | L14: =SUMIF(KeyRaces!$B$11:$B$14,CongressionalAnalysis!$C9,KeyRaces!L$11:L$14) -> 0.44 | M14: =(L14-G14)*100 -> -0.85 | N14: =SUMIF(KeyRaces!$B$11:$B$14,CongressionalAnalysis!$C9,KeyRaces!N$11:N$14) -> 12157 | O14: =SUMIF(KeyRaces!$B$11:$B$14,CongressionalAnalysis!$C9,KeyRaces!O$11:O$14) -> 0.405 | P14: =SUMIF(KeyRaces!$B$11:$B$14,CongressionalAnalysis!$C9,KeyRaces!P$11:P$14) -> 80452 | Q14: =SUMIF(KeyRaces!$B$11:$B$14,CongressionalAnalysis!$C9,KeyRaces!Q$11:Q$14) -> 0.42880061 | R14: =(Q14-$G14)*100 -> -1.9699386 | S14: =SUMIF(KeyRaces!$B$11:$B$14,CongressionalAnalysis!$C9,KeyRaces!S$11:S$14) -> 12908 | T14: =SUMIF(KeyRaces!$B$11:$B$14,CongressionalAnalysis!$C9,KeyRaces!T$11:T$14) -> 0.37836729 | U14: =SUMIF(KeyRaces!$B$11:$B$14,CongressionalAnalysis!$C9,KeyRaces!U$11:U$14) -> 84273 | V14: =SUMIF(KeyRaces!$B$11:$B$14,CongressionalAnalysis!$C9,KeyRaces!V$11:V$14) -> 0.42774699 | W14: =SUMIF(KeyRaces!$B$11:$B$14,CongressionalAnalysis!$C9,KeyRaces!W$11:W$14) -> -2.08 | X14: =SUMIF(KeyRaces!$B$11:$B$14,CongressionalAnalysis!$C9,KeyRaces!X$11:X$14) -> 3821 | Y14: =SUMIF(KeyRaces!$B$11:$B$14,CongressionalAnalysis!$C9,KeyRaces!Y$11:Y$14) -> 0.40670569 | Z14: =SUMIF(KeyRaces!$B$11:$B$14,CongressionalAnalysis!$C9,KeyRaces!Z$11:Z$14) -> 87790 | ... AN14: =SUMIF(KeyRaces!$B$11:$B$14,CongressionalAnalysis!$C9,KeyRaces!AN$11:AN$14) -> 0.34056185
C15: Republican | D15: =AJ15 -> 68713 | E15: =AK15 -> 0.32797003 | F15: =SUMIF(KeyRaces!$B$11:$B$14,CongressionalAnalysis!$C10,KeyRaces!E$11:E$14) -> 40602 | G15: =SUMIF(KeyRaces!$B$11:$B$14,CongressionalAnalysis!$C10,KeyRaces!F$11:F$14) -> 0.3288 | H15: =D15-F15 -> 28111 | I15: =H15/SUM(H14:H17) -> 0.32709269 | J15: =I15-G15 -> -0.0017073096 | K15: =SUMIF(KeyRaces!$B$11:$B$14,CongressionalAnalysis!$C10,KeyRaces!K$11:K$14) -> 49728 | L15: =SUMIF(KeyRaces!$B$11:$B$14,CongressionalAnalysis!$C10,KeyRaces!L$11:L$14) -> 0.3239 | M15: =(L15-G15)*100 -> -0.49 | N15: =SUMIF(KeyRaces!$B$11:$B$14,CongressionalAnalysis!$C10,KeyRaces!N$11:N$14) -> 9126 | O15: =SUMIF(KeyRaces!$B$11:$B$14,CongressionalAnalysis!$C10,KeyRaces!O$11:O$14) -> 0.3041 | P15: =SUMIF(KeyRaces!$B$11:$B$14,CongressionalAnalysis!$C10,KeyRaces!P$11:P$14) -> 60591 | Q15: =SUMIF(KeyRaces!$B$11:$B$14,CongressionalAnalysis!$C10,KeyRaces!Q$11:Q$14) -> 0.32294359 | R15: =(Q15-$G15)*100 -> -0.58564063 | S15: =SUMIF(KeyRaces!$B$11:$B$14,CongressionalAnalysis!$C10,KeyRaces!S$11:S$14) -> 10863 | T15: =SUMIF(KeyRaces!$B$11:$B$14,CongressionalAnalysis!$C10,KeyRaces!T$11:T$14) -> 0.31842298 | U15: =SUMIF(KeyRaces!$B$11:$B$14,CongressionalAnalysis!$C10,KeyRaces!U$11:U$14) -> 63680 | V15: =SUMIF(KeyRaces!$B$11:$B$14,CongressionalAnalysis!$C10,KeyRaces!V$11:V$14) -> 0.32322248 | W15: =SUMIF(KeyRaces!$B$11:$B$14,CongressionalAnalysis!$C10,KeyRaces!W$11:W$14) -> -0.56 | X15: =SUMIF(KeyRaces!$B$11:$B$14,CongressionalAnalysis!$C10,KeyRaces!X$11:X$14) -> 3089 | Y15: =SUMIF(KeyRaces!$B$11:$B$14,CongressionalAnalysis!$C10,KeyRaces!Y$11:Y$14) -> 0.32879191 | Z15: =SUMIF(KeyRaces!$B$11:$B$14,CongressionalAnalysis!$C10,KeyRaces!Z$11:Z$14) -> 67671 | ... AN15: =SUMIF(KeyRaces!$B$11:$B$14,CongressionalAnalysis!$C10,KeyRaces!AN$11:AN$14) -> 0.36964022
C16: DSA | D16: =AJ16 -> 51908 | E16: =AK16 -> 0.24775906 | F16: =SUMIF(KeyRaces!$B$11:$B$14,CongressionalAnalysis!$C11,KeyRaces!E$11:E$14) -> 27398 | G16: =SUMIF(KeyRaces!$B$11:$B$14,CongressionalAnalysis!$C11,KeyRaces!F$11:F$14) -> 0.2218 | H16: =D16-F16 -> 24510 | I16: =H16/SUM(H14:H17) -> 0.28519234 | J16: =I16-G16 -> 0.063392339 | K16: =SUMIF(KeyRaces!$B$11:$B$14,CongressionalAnalysis!$C11,KeyRaces!K$11:K$14) -> 36118 | L16: =SUMIF(KeyRaces!$B$11:$B$14,CongressionalAnalysis!$C11,KeyRaces!L$11:L$14) -> 0.2353 | M16: =(L16-G16)*100 -> 1.35 | N16: =SUMIF(KeyRaces!$B$11:$B$14,CongressionalAnalysis!$C11,KeyRaces!N$11:N$14) -> 8720 | O16: =SUMIF(KeyRaces!$B$11:$B$14,CongressionalAnalysis!$C11,KeyRaces!O$11:O$14) -> 0.2905 | P16: =SUMIF(KeyRaces!$B$11:$B$14,CongressionalAnalysis!$C11,KeyRaces!P$11:P$14) -> 46432 | Q16: =SUMIF(KeyRaces!$B$11:$B$14,CongressionalAnalysis!$C11,KeyRaces!Q$11:Q$14) -> 0.24747763 | R16: =(Q16-$G16)*100 -> 2.5677628 | S16: =SUMIF(KeyRaces!$B$11:$B$14,CongressionalAnalysis!$C11,KeyRaces!S$11:S$14) -> 10314 | T16: =SUMIF(KeyRaces!$B$11:$B$14,CongressionalAnalysis!$C11,KeyRaces!T$11:T$14) -> 0.30233035 | U16: =SUMIF(KeyRaces!$B$11:$B$14,CongressionalAnalysis!$C11,KeyRaces!U$11:U$14) -> 48898 | V16: =SUMIF(KeyRaces!$B$11:$B$14,CongressionalAnalysis!$C11,KeyRaces!V$11:V$14) -> 0.24819304 | W16: =SUMIF(KeyRaces!$B$11:$B$14,CongressionalAnalysis!$C11,KeyRaces!W$11:W$14) -> 2.64 | X16: =SUMIF(KeyRaces!$B$11:$B$14,CongressionalAnalysis!$C11,KeyRaces!X$11:X$14) -> 2466 | Y16: =SUMIF(KeyRaces!$B$11:$B$14,CongressionalAnalysis!$C11,KeyRaces!Y$11:Y$14) -> 0.26248004 | Z16: =SUMIF(KeyRaces!$B$11:$B$14,CongressionalAnalysis!$C11,KeyRaces!Z$11:Z$14) -> 51168 | ... AN16: =SUMIF(KeyRaces!$B$11:$B$14,CongressionalAnalysis!$C11,KeyRaces!AN$11:AN$14) -> 0.28831937
C17: Independent | D17: =AJ17 -> 0 | E17: =AK17 -> 0 | F17: =SUMIF(KeyRaces!$B$11:$B$14,CongressionalAnalysis!$C12,KeyRaces!E$11:E$14) -> 0 | G17: =SUMIF(KeyRaces!$B$11:$B$14,CongressionalAnalysis!$C12,KeyRaces!F$11:F$14) -> 0 | H17: =D17-F17 -> 0 | I17: =H17/SUM(H14:H17) -> 0 | J17: =I17-G17 -> 0 | K17: =SUMIF(KeyRaces!$B$11:$B$14,CongressionalAnalysis!$C12,KeyRaces!K$11:K$14) -> 0 | L17: =SUMIF(KeyRaces!$B$11:$B$14,CongressionalAnalysis!$C12,KeyRaces!L$11:L$14) -> 0 | M17: =(L17-G17)*100 -> 0 | N17: =SUMIF(KeyRaces!$B$11:$B$14,CongressionalAnalysis!$C12,KeyRaces!N$11:N$14) -> 0 | O17: =SUMIF(KeyRaces!$B$11:$B$14,CongressionalAnalysis!$C12,KeyRaces!O$11:O$14) -> 0 | P17: =SUMIF(KeyRaces!$B$11:$B$14,CongressionalAnalysis!$C12,KeyRaces!P$11:P$14) -> 0 | Q17: =SUMIF(KeyRaces!$B$11:$B$14,CongressionalAnalysis!$C12,KeyRaces!Q$11:Q$14) -> 0 | R17: =(Q17-$G17)*100 -> 0 | S17: =SUMIF(KeyRaces!$B$11:$B$14,CongressionalAnalysis!$C12,KeyRaces!S$11:S$14) -> 0 | T17: =SUMIF(KeyRaces!$B$11:$B$14,CongressionalAnalysis!$C12,KeyRaces!T$11:T$14) -> 0 | U17: =SUMIF(KeyRaces!$B$11:$B$14,CongressionalAnalysis!$C12,KeyRaces!U$11:U$14) -> 0 | V17: =SUMIF(KeyRaces!$B$11:$B$14,CongressionalAnalysis!$C12,KeyRaces!V$11:V$14) -> 0 | W17: =SUMIF(KeyRaces!$B$11:$B$14,CongressionalAnalysis!$C12,KeyRaces!W$11:W$14) -> 0 | X17: =SUMIF(KeyRaces!$B$11:$B$14,CongressionalAnalysis!$C12,KeyRaces!X$11:X$14) -> 0 | Y17: =SUMIF(KeyRaces!$B$11:$B$14,CongressionalAnalysis!$C12,KeyRaces!Y$11:Y$14) -> 0 | Z17: =SUMIF(KeyRaces!$B$11:$B$14,CongressionalAnalysis!$C12,KeyRaces!Z$11:Z$14) -> 0 | ... AN17: =SUMIF(KeyRaces!$B$11:$B$14,CongressionalAnalysis!$C12,KeyRaces!AN$11:AN$14) -> 0
B18: District 3 - Southwest WA | C18: Total Ballots | D18: =AJ18 -> 216864 | F18: =KeyRaces!E15 -> 140669 | G18: =KeyRaces!F15 | H18: =D18-F18 -> 76195 | K18: =KeyRaces!K15 -> 175609 | L18: =KeyRaces!L15 | N18: =KeyRaces!N15 -> 34940 | O18: =KeyRaces!O15 | P18: =KeyRaces!P15 -> 206503 | Q18: =KeyRaces!Q15 | S18: =KeyRaces!S15 -> 30894 | T18: =KeyRaces!T15 | U18: =KeyRaces!U15 -> 210175 | V18: =KeyRaces!V15 | W18: =KeyRaces!W15 | X18: =KeyRaces!X15 -> 3672 | Y18: =KeyRaces!Y15 | Z18: =KeyRaces!Z15 -> 214816 | ... AN18: =KeyRaces!AN15 -> 0
C19: Democratic | D19: =AJ19 -> 81739 | E19: =AK19 -> 0.38108359 | F19: =SUMIF(KeyRaces!$B$16:$B$24,CongressionalAnalysis!$C14,KeyRaces!E$16:E$24) -> 56513 | G19: =SUMIF(KeyRaces!$B$16:$B$24,CongressionalAnalysis!$C14,KeyRaces!F$16:F$24) -> 0.4061 | H19: =D19-F19 -> 25226 | I19: =H19/SUM(H19:H22) -> 0.33515352 | J19: =I19-G19 -> -0.07094648 | K19: =SUMIF(KeyRaces!$B$16:$B$24,CongressionalAnalysis!$C14,KeyRaces!K$16:K$24) -> 68179 | L19: =SUMIF(KeyRaces!$B$16:$B$24,CongressionalAnalysis!$C14,KeyRaces!L$16:L$24) -> 0.3923 | M19: =(L19-G19)*100 -> -1.38 | N19: =SUMIF(KeyRaces!$B$16:$B$24,CongressionalAnalysis!$C14,KeyRaces!N$16:N$24) -> 11666 | O19: =SUMIF(KeyRaces!$B$16:$B$24,CongressionalAnalysis!$C14,KeyRaces!O$16:O$24) -> 0.3368 | P19: =SUMIF(KeyRaces!$B$16:$B$24,CongressionalAnalysis!$C14,KeyRaces!P$16:P$24) -> 78533 | Q19: =SUMIF(KeyRaces!$B$16:$B$24,CongressionalAnalysis!$C14,KeyRaces!Q$16:Q$24) -> 0.38420481 | R19: =(Q19-$G19)*100 -> -2.189519 | S19: =SUMIF(KeyRaces!$B$16:$B$24,CongressionalAnalysis!$C14,KeyRaces!S$16:S$24) -> 10354 | T19: =SUMIF(KeyRaces!$B$16:$B$24,CongressionalAnalysis!$C14,KeyRaces!T$16:T$24) -> 0.33839919 | U19: =SUMIF(KeyRaces!$B$16:$B$24,CongressionalAnalysis!$C14,KeyRaces!U$16:U$24) -> 79527 | V19: =SUMIF(KeyRaces!$B$16:$B$24,CongressionalAnalysis!$C14,KeyRaces!V$16:V$24) -> 0.38233767 | W19: =SUMIF(KeyRaces!$B$16:$B$24,CongressionalAnalysis!$C14,KeyRaces!W$16:W$24) -> -2.38 | X19: =SUMIF(KeyRaces!$B$16:$B$24,CongressionalAnalysis!$C14,KeyRaces!X$16:X$24) -> 994 | Y19: =SUMIF(KeyRaces!$B$16:$B$24,CongressionalAnalysis!$C14,KeyRaces!Y$16:Y$24) -> 0.27626459 | Z19: =SUMIF(KeyRaces!$B$16:$B$24,CongressionalAnalysis!$C14,KeyRaces!Z$16:Z$24) -> 81124 | ... AN19: =SUMIF(KeyRaces!$B$16:$B$24,CongressionalAnalysis!$C14,KeyRaces!AN$16:AN$24) -> 0.30495979
C20: Republican | D20: =AJ20 -> 91893 | E20: =AK20 -> 0.42842357 | F20: =SUMIF(KeyRaces!$B$16:$B$24,CongressionalAnalysis!$C15,KeyRaces!E$16:E$24) -> 58392 | G20: =SUMIF(KeyRaces!$B$16:$B$24,CongressionalAnalysis!$C15,KeyRaces!F$16:F$24) -> 0.4196 | H20: =D20-F20 -> 33501 | I20: =H20/SUM(H19:H22) -> 0.44509546 | J20: =I20-G20 -> 0.02549546 | K20: =SUMIF(KeyRaces!$B$16:$B$24,CongressionalAnalysis!$C15,KeyRaces!K$16:K$24) -> 73781 | L20: =SUMIF(KeyRaces!$B$16:$B$24,CongressionalAnalysis!$C15,KeyRaces!L$16:L$24) -> 0.4245 | M20: =(L20-G20)*100 -> 0.49 | N20: =SUMIF(KeyRaces!$B$16:$B$24,CongressionalAnalysis!$C15,KeyRaces!N$16:N$24) -> 15389 | O20: =SUMIF(KeyRaces!$B$16:$B$24,CongressionalAnalysis!$C15,KeyRaces!O$16:O$24) -> 0.4444 | P20: =SUMIF(KeyRaces!$B$16:$B$24,CongressionalAnalysis!$C15,KeyRaces!P$16:P$24) -> 86786 | Q20: =SUMIF(KeyRaces!$B$16:$B$24,CongressionalAnalysis!$C15,KeyRaces!Q$16:Q$24) -> 0.42458073 | R20: =(Q20-$G20)*100 -> 0.49807323 | S20: =SUMIF(KeyRaces!$B$16:$B$24,CongressionalAnalysis!$C15,KeyRaces!S$16:S$24) -> 13005 | T20: =SUMIF(KeyRaces!$B$16:$B$24,CongressionalAnalysis!$C15,KeyRaces!T$16:T$24) -> 0.42504167 | U20: =SUMIF(KeyRaces!$B$16:$B$24,CongressionalAnalysis!$C15,KeyRaces!U$16:U$24) -> 88754 | V20: =SUMIF(KeyRaces!$B$16:$B$24,CongressionalAnalysis!$C15,KeyRaces!V$16:V$24) -> 0.42669782 | W20: =SUMIF(KeyRaces!$B$16:$B$24,CongressionalAnalysis!$C15,KeyRaces!W$16:W$24) -> 0.71 | X20: =SUMIF(KeyRaces!$B$16:$B$24,CongressionalAnalysis!$C15,KeyRaces!X$16:X$24) -> 1968 | Y20: =SUMIF(KeyRaces!$B$16:$B$24,CongressionalAnalysis!$C15,KeyRaces!Y$16:Y$24) -> 0.54697054 | Z20: =SUMIF(KeyRaces!$B$16:$B$24,CongressionalAnalysis!$C15,KeyRaces!Z$16:Z$24) -> 90873 | ... AN20: =SUMIF(KeyRaces!$B$16:$B$24,CongressionalAnalysis!$C15,KeyRaces!AN$16:AN$24) -> 0.53351206
C21: DSA | D21: =AJ21 -> 35820 | E21: =AK21 -> 0.16700001 | F21: =SUMIF(KeyRaces!$B$16:$B$24,CongressionalAnalysis!$C16,KeyRaces!E$16:E$24) -> 21290 | G21: =SUMIF(KeyRaces!$B$16:$B$24,CongressionalAnalysis!$C16,KeyRaces!F$16:F$24) -> 0.153 | H21: =D21-F21 -> 14530 | I21: =H21/SUM(H19:H22) -> 0.19304609 | J21: =I21-G21 -> 0.040046089 | K21: =SUMIF(KeyRaces!$B$16:$B$24,CongressionalAnalysis!$C16,KeyRaces!K$16:K$24) -> 28062 | L21: =SUMIF(KeyRaces!$B$16:$B$24,CongressionalAnalysis!$C16,KeyRaces!L$16:L$24) -> 0.1615 | M21: =(L21-G21)*100 -> 0.85 | N21: =SUMIF(KeyRaces!$B$16:$B$24,CongressionalAnalysis!$C16,KeyRaces!N$16:N$24) -> 6772 | O21: =SUMIF(KeyRaces!$B$16:$B$24,CongressionalAnalysis!$C16,KeyRaces!O$16:O$24) -> 0.1955 | P21: =SUMIF(KeyRaces!$B$16:$B$24,CongressionalAnalysis!$C16,KeyRaces!P$16:P$24) -> 34479 | Q21: =SUMIF(KeyRaces!$B$16:$B$24,CongressionalAnalysis!$C16,KeyRaces!Q$16:Q$24) -> 0.16868065 | R21: =(Q21-$G21)*100 -> 1.5680652 | S21: =SUMIF(KeyRaces!$B$16:$B$24,CongressionalAnalysis!$C16,KeyRaces!S$16:S$24) -> 6417 | T21: =SUMIF(KeyRaces!$B$16:$B$24,CongressionalAnalysis!$C16,KeyRaces!T$16:T$24) -> 0.20972644 | U21: =SUMIF(KeyRaces!$B$16:$B$24,CongressionalAnalysis!$C16,KeyRaces!U$16:U$24) -> 34927 | V21: =SUMIF(KeyRaces!$B$16:$B$24,CongressionalAnalysis!$C16,KeyRaces!V$16:V$24) -> 0.16791665 | W21: =SUMIF(KeyRaces!$B$16:$B$24,CongressionalAnalysis!$C16,KeyRaces!W$16:W$24) -> 1.49 | X21: =SUMIF(KeyRaces!$B$16:$B$24,CongressionalAnalysis!$C16,KeyRaces!X$16:X$24) -> 448 | Y21: =SUMIF(KeyRaces!$B$16:$B$24,CongressionalAnalysis!$C16,KeyRaces!Y$16:Y$24) -> 0.12451362 | Z21: =SUMIF(KeyRaces!$B$16:$B$24,CongressionalAnalysis!$C16,KeyRaces!Z$16:Z$24) -> 35540 | ... AN21: =SUMIF(KeyRaces!$B$16:$B$24,CongressionalAnalysis!$C16,KeyRaces!AN$16:AN$24) -> 0.12198391
C22: Independent | D22: =AJ22 -> 4894 | E22: =AK22 -> 0.022816808 | F22: =SUMIF(KeyRaces!$B$16:$B$24,CongressionalAnalysis!$C17,KeyRaces!E$16:E$24) -> 2884 | G22: =SUMIF(KeyRaces!$B$16:$B$24,CongressionalAnalysis!$C17,KeyRaces!F$16:F$24) -> 0.0207 | H22: =D22-F22 -> 2010 | I22: =H22/SUM(H19:H22) -> 0.02670493 | J22: =I22-G22 -> 0.0060049304 | K22: =SUMIF(KeyRaces!$B$16:$B$24,CongressionalAnalysis!$C17,KeyRaces!K$16:K$24) -> 3673 | L22: =SUMIF(KeyRaces!$B$16:$B$24,CongressionalAnalysis!$C17,KeyRaces!L$16:L$24) -> 0.0212 | M22: =(L22-G22)*100 -> 0.05 | N22: =SUMIF(KeyRaces!$B$16:$B$24,CongressionalAnalysis!$C17,KeyRaces!N$16:N$24) -> 789 | O22: =SUMIF(KeyRaces!$B$16:$B$24,CongressionalAnalysis!$C17,KeyRaces!O$16:O$24) -> 0.0228 | P22: =SUMIF(KeyRaces!$B$16:$B$24,CongressionalAnalysis!$C17,KeyRaces!P$16:P$24) -> 4475 | Q22: =SUMIF(KeyRaces!$B$16:$B$24,CongressionalAnalysis!$C17,KeyRaces!Q$16:Q$24) -> 0.021892918 | R22: =(Q22-$G22)*100 -> 0.11929179 | S22: =SUMIF(KeyRaces!$B$16:$B$24,CongressionalAnalysis!$C17,KeyRaces!S$16:S$24) -> 802 | T22: =SUMIF(KeyRaces!$B$16:$B$24,CongressionalAnalysis!$C17,KeyRaces!T$16:T$24) -> 0.02621172 | U22: =SUMIF(KeyRaces!$B$16:$B$24,CongressionalAnalysis!$C17,KeyRaces!U$16:U$24) -> 4654 | V22: =SUMIF(KeyRaces!$B$16:$B$24,CongressionalAnalysis!$C17,KeyRaces!V$16:V$24) -> 0.022374785 | W22: =SUMIF(KeyRaces!$B$16:$B$24,CongressionalAnalysis!$C17,KeyRaces!W$16:W$24) -> 0.16 | X22: =SUMIF(KeyRaces!$B$16:$B$24,CongressionalAnalysis!$C17,KeyRaces!X$16:X$24) -> 179 | Y22: =SUMIF(KeyRaces!$B$16:$B$24,CongressionalAnalysis!$C17,KeyRaces!Y$16:Y$24) -> 0.049749861 | Z22: =SUMIF(KeyRaces!$B$16:$B$24,CongressionalAnalysis!$C17,KeyRaces!Z$16:Z$24) -> 4813 | ... AN22: =SUMIF(KeyRaces!$B$16:$B$24,CongressionalAnalysis!$C17,KeyRaces!AN$16:AN$24) -> 0.042895442
B23: District 4 - Central WA | C23: Total Ballots | D23: =AJ23 -> 145781 | F23: =KeyRaces!E25 -> 75273 | G23: =KeyRaces!F25 | H23: =D23-F23 -> 70508 | K23: =KeyRaces!K25 -> 93309 | L23: =KeyRaces!L25 | N23: =KeyRaces!N25 -> 18036 | O23: =KeyRaces!O25 | P23: =KeyRaces!P25 -> 106450 | Q23: =KeyRaces!Q25 | S23: =KeyRaces!S25 -> 13141 | T23: =KeyRaces!T25 | U23: =KeyRaces!U25 -> 135665 | V23: =KeyRaces!V25 | W23: =KeyRaces!W25 | X23: =KeyRaces!X25 -> 29215 | Y23: =KeyRaces!Y25 | Z23: =KeyRaces!Z25 -> 143270 | ... AN23: =KeyRaces!AN25 -> 0
C24: Democratic | D24: =AJ24 -> 42681 | E24: =AK24 -> 0.29917777 | F24: =SUMIF(KeyRaces!$B$26:$B$36,CongressionalAnalysis!$C19,KeyRaces!E$26:E$36) -> 22657 | G24: =SUMIF(KeyRaces!$B$26:$B$36,CongressionalAnalysis!$C19,KeyRaces!F$26:F$36) -> 0.308 | H24: =D24-F24 -> 20024 | I24: =H24/SUM(H24:H27) -> 0.28992978 | J24: =I24-G24 -> -0.018070224 | K24: =SUMIF(KeyRaces!$B$26:$B$36,CongressionalAnalysis!$C19,KeyRaces!K$26:K$36) -> 27963 | L24: =SUMIF(KeyRaces!$B$26:$B$36,CongressionalAnalysis!$C19,KeyRaces!L$26:L$36) -> 0.3067 | M24: =(L24-G24)*100 -> -0.13 | N24: =SUMIF(KeyRaces!$B$26:$B$36,CongressionalAnalysis!$C19,KeyRaces!N$26:N$36) -> 5306 | O24: =SUMIF(KeyRaces!$B$26:$B$36,CongressionalAnalysis!$C19,KeyRaces!O$26:O$36) -> 0.3012 | P24: =SUMIF(KeyRaces!$B$26:$B$36,CongressionalAnalysis!$C19,KeyRaces!P$26:P$36) -> 31659 | Q24: =SUMIF(KeyRaces!$B$26:$B$36,CongressionalAnalysis!$C19,KeyRaces!Q$26:Q$36) -> 0.30414441 | R24: =(Q24-$G24)*100 -> -0.38555893 | S24: =SUMIF(KeyRaces!$B$26:$B$36,CongressionalAnalysis!$C19,KeyRaces!S$26:S$36) -> 3696 | T24: =SUMIF(KeyRaces!$B$26:$B$36,CongressionalAnalysis!$C19,KeyRaces!T$26:T$36) -> 0.2860017 | U24: =SUMIF(KeyRaces!$B$26:$B$36,CongressionalAnalysis!$C19,KeyRaces!U$26:U$36) -> 39911 | V24: =SUMIF(KeyRaces!$B$26:$B$36,CongressionalAnalysis!$C19,KeyRaces!V$26:V$36) -> 0.30034918 | W24: =SUMIF(KeyRaces!$B$26:$B$36,CongressionalAnalysis!$C19,KeyRaces!W$26:W$36) -> -0.77 | X24: =SUMIF(KeyRaces!$B$26:$B$36,CongressionalAnalysis!$C19,KeyRaces!X$26:X$36) -> 8252 | Y24: =SUMIF(KeyRaces!$B$26:$B$36,CongressionalAnalysis!$C19,KeyRaces!Y$26:Y$36) -> 0.2866273 | Z24: =SUMIF(KeyRaces!$B$26:$B$36,CongressionalAnalysis!$C19,KeyRaces!Z$26:Z$36) -> 41998 | ... AN24: =SUMIF(KeyRaces!$B$26:$B$36,CongressionalAnalysis!$C19,KeyRaces!AN$26:AN$36) -> 0.31172545
C25: Republican | D25: =AJ25 -> 89917 | E25: =AK25 -> 0.63028438 | F25: =SUMIF(KeyRaces!$B$26:$B$36,CongressionalAnalysis!$C20,KeyRaces!E$26:E$36) -> 45990 | G25: =SUMIF(KeyRaces!$B$26:$B$36,CongressionalAnalysis!$C20,KeyRaces!F$26:F$36) -> 0.6252 | H25: =D25-F25 -> 43927 | I25: =H25/SUM(H24:H27) -> 0.63602404 | J25: =I25-G25 -> 0.010824035 | K25: =SUMIF(KeyRaces!$B$26:$B$36,CongressionalAnalysis!$C20,KeyRaces!K$26:K$36) -> 57076 | L25: =SUMIF(KeyRaces!$B$26:$B$36,CongressionalAnalysis!$C20,KeyRaces!L$26:L$36) -> 0.6261 | M25: =(L25-G25)*100 -> 0.09 | N25: =SUMIF(KeyRaces!$B$26:$B$36,CongressionalAnalysis!$C20,KeyRaces!N$26:N$36) -> 11086 | O25: =SUMIF(KeyRaces!$B$26:$B$36,CongressionalAnalysis!$C20,KeyRaces!O$26:O$36) -> 0.6293 | P25: =SUMIF(KeyRaces!$B$26:$B$36,CongressionalAnalysis!$C20,KeyRaces!P$26:P$36) -> 65280 | Q25: =SUMIF(KeyRaces!$B$26:$B$36,CongressionalAnalysis!$C20,KeyRaces!Q$26:Q$36) -> 0.62713753 | R25: =(Q25-$G25)*100 -> 0.19375322 | S25: =SUMIF(KeyRaces!$B$26:$B$36,CongressionalAnalysis!$C20,KeyRaces!S$26:S$36) -> 8204 | T25: =SUMIF(KeyRaces!$B$26:$B$36,CongressionalAnalysis!$C20,KeyRaces!T$26:T$36) -> 0.63483711 | U25: =SUMIF(KeyRaces!$B$26:$B$36,CongressionalAnalysis!$C20,KeyRaces!U$26:U$36) -> 83683 | V25: =SUMIF(KeyRaces!$B$26:$B$36,CongressionalAnalysis!$C20,KeyRaces!V$26:V$36) -> 0.62975422 | W25: =SUMIF(KeyRaces!$B$26:$B$36,CongressionalAnalysis!$C20,KeyRaces!W$26:W$36) -> 0.45 | X25: =SUMIF(KeyRaces!$B$26:$B$36,CongressionalAnalysis!$C20,KeyRaces!X$26:X$36) -> 18403 | Y25: =SUMIF(KeyRaces!$B$26:$B$36,CongressionalAnalysis!$C20,KeyRaces!Y$26:Y$36) -> 0.63921501 | Z25: =SUMIF(KeyRaces!$B$26:$B$36,CongressionalAnalysis!$C20,KeyRaces!Z$26:Z$36) -> 88384 | ... AN25: =SUMIF(KeyRaces!$B$26:$B$36,CongressionalAnalysis!$C20,KeyRaces!AN$26:AN$36) -> 0.59199237
C26: DSA | D26: =AJ26 -> 0 | E26: =AK26 -> 0 | F26: =SUMIF(KeyRaces!$B$26:$B$36,CongressionalAnalysis!$C21,KeyRaces!E$26:E$36) -> 0 | G26: =SUMIF(KeyRaces!$B$26:$B$36,CongressionalAnalysis!$C21,KeyRaces!F$26:F$36) -> 0 | H26: =D26-F26 -> 0 | I26: =H26/SUM(H24:H27) -> 0 | J26: =I26-G26 -> 0 | K26: =SUMIF(KeyRaces!$B$26:$B$36,CongressionalAnalysis!$C21,KeyRaces!K$26:K$36) -> 0 | L26: =SUMIF(KeyRaces!$B$26:$B$36,CongressionalAnalysis!$C21,KeyRaces!L$26:L$36) -> 0 | M26: =(L26-G26)*100 -> 0 | N26: =SUMIF(KeyRaces!$B$26:$B$36,CongressionalAnalysis!$C21,KeyRaces!N$26:N$36) -> 0 | O26: =SUMIF(KeyRaces!$B$26:$B$36,CongressionalAnalysis!$C21,KeyRaces!O$26:O$36) -> 0 | P26: =SUMIF(KeyRaces!$B$26:$B$36,CongressionalAnalysis!$C21,KeyRaces!P$26:P$36) -> 0 | Q26: =SUMIF(KeyRaces!$B$26:$B$36,CongressionalAnalysis!$C21,KeyRaces!Q$26:Q$36) -> 0 | R26: =(Q26-$G26)*100 -> 0 | S26: =SUMIF(KeyRaces!$B$26:$B$36,CongressionalAnalysis!$C21,KeyRaces!S$26:S$36) -> 0 | T26: =SUMIF(KeyRaces!$B$26:$B$36,CongressionalAnalysis!$C21,KeyRaces!T$26:T$36) -> 0 | U26: =SUMIF(KeyRaces!$B$26:$B$36,CongressionalAnalysis!$C21,KeyRaces!U$26:U$36) -> 0 | V26: =SUMIF(KeyRaces!$B$26:$B$36,CongressionalAnalysis!$C21,KeyRaces!V$26:V$36) -> 0 | W26: =SUMIF(KeyRaces!$B$26:$B$36,CongressionalAnalysis!$C21,KeyRaces!W$26:W$36) -> 0 | X26: =SUMIF(KeyRaces!$B$26:$B$36,CongressionalAnalysis!$C21,KeyRaces!X$26:X$36) -> 0 | Y26: =SUMIF(KeyRaces!$B$26:$B$36,CongressionalAnalysis!$C21,KeyRaces!Y$26:Y$36) -> 0 | Z26: =SUMIF(KeyRaces!$B$26:$B$36,CongressionalAnalysis!$C21,KeyRaces!Z$26:Z$36) -> 0 | ... AN26: =SUMIF(KeyRaces!$B$26:$B$36,CongressionalAnalysis!$C21,KeyRaces!AN$26:AN$36) -> 0
C27: Independent | D27: =AJ27 -> 9946 | E27: =AK27 -> 0.069717722 | F27: =SUMIF(KeyRaces!$B$26:$B$36,CongressionalAnalysis!$C22,KeyRaces!E$26:E$36) -> 4832 | G27: =SUMIF(KeyRaces!$B$26:$B$36,CongressionalAnalysis!$C22,KeyRaces!F$26:F$36) -> 0.0657 | H27: =D27-F27 -> 5114 | I27: =H27/SUM(H24:H27) -> 0.074046188 | J27: =I27-G27 -> 0.0083461884 | K27: =SUMIF(KeyRaces!$B$26:$B$36,CongressionalAnalysis!$C22,KeyRaces!K$26:K$36) -> 6043 | L27: =SUMIF(KeyRaces!$B$26:$B$36,CongressionalAnalysis!$C22,KeyRaces!L$26:L$36) -> 0.0662 | M27: =(L27-G27)*100 -> 0.05 | N27: =SUMIF(KeyRaces!$B$26:$B$36,CongressionalAnalysis!$C22,KeyRaces!N$26:N$36) -> 1211 | O27: =SUMIF(KeyRaces!$B$26:$B$36,CongressionalAnalysis!$C22,KeyRaces!O$26:O$36) -> 0.0687 | P27: =SUMIF(KeyRaces!$B$26:$B$36,CongressionalAnalysis!$C22,KeyRaces!P$26:P$36) -> 7056 | Q27: =SUMIF(KeyRaces!$B$26:$B$36,CongressionalAnalysis!$C22,KeyRaces!Q$26:Q$36) -> 0.067786189 | R27: =(Q27-$G27)*100 -> 0.20861891 | S27: =SUMIF(KeyRaces!$B$26:$B$36,CongressionalAnalysis!$C22,KeyRaces!S$26:S$36) -> 1013 | T27: =SUMIF(KeyRaces!$B$26:$B$36,CongressionalAnalysis!$C22,KeyRaces!T$26:T$36) -> 0.078387371 | U27: =SUMIF(KeyRaces!$B$26:$B$36,CongressionalAnalysis!$C22,KeyRaces!U$26:U$36) -> 9180 | V27: =SUMIF(KeyRaces!$B$26:$B$36,CongressionalAnalysis!$C22,KeyRaces!V$26:V$36) -> 0.069083849 | W27: =SUMIF(KeyRaces!$B$26:$B$36,CongressionalAnalysis!$C22,KeyRaces!W$26:W$36) -> 0.33 | X27: =SUMIF(KeyRaces!$B$26:$B$36,CongressionalAnalysis!$C22,KeyRaces!X$26:X$36) -> 2124 | Y27: =SUMIF(KeyRaces!$B$26:$B$36,CongressionalAnalysis!$C22,KeyRaces!Y$26:Y$36) -> 0.073775617 | Z27: =SUMIF(KeyRaces!$B$26:$B$36,CongressionalAnalysis!$C22,KeyRaces!Z$26:Z$36) -> 9739 | ... AN27: =SUMIF(KeyRaces!$B$26:$B$36,CongressionalAnalysis!$C22,KeyRaces!AN$26:AN$36) -> 0.10009533
B28: District 5 - Eastern WA | C28: Total Ballots | D28: =AJ28 -> 191653 | F28: =KeyRaces!E37 -> 105659 | G28: =KeyRaces!F37 | H28: =D28-F28 -> 85994 | K28: =KeyRaces!K37 -> 119831 | L28: =KeyRaces!L37 | N28: =KeyRaces!N37 -> 14172 | O28: =KeyRaces!O37 | P28: =KeyRaces!P37 -> 136944 | Q28: =KeyRaces!Q37 | S28: =KeyRaces!S37 -> 17113 | T28: =KeyRaces!T37 | U28: =KeyRaces!U37 -> 142533 | V28: =KeyRaces!V37 | W28: =KeyRaces!W37 | X28: =KeyRaces!X37 -> 5589 | Y28: =KeyRaces!Y37 | Z28: =KeyRaces!Z37 -> 176966 | ... AN28: =KeyRaces!AN37 -> 0
C29: Democratic | D29: =AJ29 -> 56229 | E29: =AK29 -> 0.27535025 | F29: =SUMIF(KeyRaces!$B$38:$B$49,CongressionalAnalysis!$C24,KeyRaces!E$38:E$49) -> 33615 | G29: =SUMIF(KeyRaces!$B$38:$B$49,CongressionalAnalysis!$C24,KeyRaces!F$38:F$49) -> 0.2975 | H29: =D29-F29 -> 22614 | I29: =H29/SUM(H29:H32) -> 0.24811288 | J29: =I29-G29 -> -0.049387124 | K29: =SUMIF(KeyRaces!$B$38:$B$49,CongressionalAnalysis!$C24,KeyRaces!K$38:K$49) -> 37720 | L29: =SUMIF(KeyRaces!$B$38:$B$49,CongressionalAnalysis!$C24,KeyRaces!L$38:L$49) -> 0.2971 | M29: =(L29-G29)*100 -> -0.04 | N29: =SUMIF(KeyRaces!$B$38:$B$49,CongressionalAnalysis!$C24,KeyRaces!N$38:N$49) -> 4105 | O29: =SUMIF(KeyRaces!$B$38:$B$49,CongressionalAnalysis!$C24,KeyRaces!O$38:O$49) -> 0.2935 | P29: =SUMIF(KeyRaces!$B$38:$B$49,CongressionalAnalysis!$C24,KeyRaces!P$38:P$49) -> 41779 | Q29: =SUMIF(KeyRaces!$B$38:$B$49,CongressionalAnalysis!$C24,KeyRaces!Q$38:Q$49) -> 0.29042439 | R29: =(Q29-$G29)*100 -> -0.70756143 | S29: =SUMIF(KeyRaces!$B$38:$B$49,CongressionalAnalysis!$C24,KeyRaces!S$38:S$49) -> 4059 | T29: =SUMIF(KeyRaces!$B$38:$B$49,CongressionalAnalysis!$C24,KeyRaces!T$38:T$49) -> 0.2405761 | U29: =SUMIF(KeyRaces!$B$38:$B$49,CongressionalAnalysis!$C24,KeyRaces!U$38:U$49) -> 43853 | V29: =SUMIF(KeyRaces!$B$38:$B$49,CongressionalAnalysis!$C24,KeyRaces!V$38:V$49) -> 0.28876305 | W29: =SUMIF(KeyRaces!$B$38:$B$49,CongressionalAnalysis!$C24,KeyRaces!W$38:W$49) -> -0.87 | X29: =SUMIF(KeyRaces!$B$38:$B$49,CongressionalAnalysis!$C24,KeyRaces!X$38:X$49) -> 2074 | Y29: =SUMIF(KeyRaces!$B$38:$B$49,CongressionalAnalysis!$C24,KeyRaces!Y$38:Y$49) -> 0.25892634 | Z29: =SUMIF(KeyRaces!$B$38:$B$49,CongressionalAnalysis!$C24,KeyRaces!Z$38:Z$49) -> 52138 | ... AN29: =SUMIF(KeyRaces!$B$38:$B$49,CongressionalAnalysis!$C24,KeyRaces!AN$38:AN$49) -> 0.22925338
